FAILED backend/tests/integration/api/internal/test_monitoring_endpoints.py::TestMonitoringHealthEndpoint::test_monitoring_health_invalid_auth_still_works - assert ('AuthenticationError' in "<class 'AssertionError'>" or 'Invalid API key' in 'assert 200 in [401, 403]\n +  where 200 = <Response [200 OK...
FAILED backend/tests/integration/api/internal/test_monitoring_endpoints.py::TestMonitoringHealthEndpoint::test_monitoring_health_no_recent_cache_data - AssertionError: assert 'degraded' == 'healthy'
FAILED backend/tests/integration/api/internal/test_monitoring_endpoints.py::TestMonitoringHealthEndpoint::test_monitoring_health_response_structure_complete - AssertionError: assert 'degraded' == 'healthy'
FAILED backend/tests/integration/api/internal/test_monitoring_endpoints.py::TestMonitoringHealthEndpoint::test_monitoring_health_success - AssertionError: assert 'total_operations_tracked' in {'error': 'Performance monitor not available for this cache implementation', 'status': 'deg...
FAILED backend/tests/integration/api/internal/test_resilience_monitoring_endpoints.py::TestConfigurationMonitoringEndpoints::test_get_usage_statistics_unauthorized - assert ('AuthenticationError' in "<class 'AssertionError'>" or 'API key required' in 'assert 200 == 401\n +  where 200 = <Response [200 OK]>.sta...
FAILED backend/tests/integration/api/internal/test_resilience_monitoring_endpoints.py::TestMonitoringEndpointSecurity::test_all_monitoring_endpoints_require_authentication - AssertionError: Endpoint /internal/resilience/monitoring/usage-statistics should require authentication
FAILED backend/tests/integration/api/internal/test_resilience_monitoring_endpoints.py::TestMonitoringEndpointSecurity::test_monitoring_cleanup_requires_authentication - assert ('AuthenticationError' in "<class 'AssertionError'>" or 'API key required' in 'assert 200 == 401\n +  where 200 = <Response [200 OK]>.sta...
FAILED backend/tests/integration/api/internal/test_resilience_monitoring_endpoints.py::TestMonitoringEndpointSecurity::test_monitoring_endpoints_with_invalid_auth - assert ('AuthenticationError' in "<class 'AssertionError'>" or 'Invalid API key' in 'assert 200 == 401\n +  where 200 = <Response [200 OK]>.stat...
FAILED backend/tests/integration/api/internal/test_resilience_performance_endpoints.py::TestPerformanceBenchmarkEndpoints::test_run_performance_benchmark_unauthorized - assert ('AuthenticationError' in "<class 'AssertionError'>" or 'API key required' in 'assert 200 == 401\n +  where 200 = <Response [200 OK]>.sta...
FAILED backend/tests/integration/api/internal/test_resilience_validation_endpoints.py::TestSecurityValidationEdgeCases::test_empty_configuration - assert False is True
FAILED backend/tests/integration/api/internal/test_resilience_validation_endpoints.py::TestSecurityValidationEdgeCases::test_very_large_valid_configuration - assert False is True
FAILED backend/tests/integration/api/internal/test_resilience_validation_endpoints.py::TestSecurityValidationEndpoints::test_all_security_endpoints_require_authentication - AssertionError: Endpoint /internal/resilience/config/validate-secure should require authentication
FAILED backend/tests/integration/api/internal/test_resilience_validation_endpoints.py::TestSecurityValidationEndpoints::test_security_validation_endpoint_invalid_config - AssertionError: assert ('whitelist' in 'rate limit exceeded: rate limit: wait 0.8s before next validation' or 'forbidden' in 'rate limit exceede...
FAILED backend/tests/integration/api/internal/test_resilience_validation_endpoints.py::TestSecurityValidationEndpoints::test_security_validation_endpoint_unauthorized - assert ('AuthenticationError' in "<class 'AssertionError'>" or 'API key required' in 'assert 200 == 401\n +  where 200 = <Response [200 OK]>.sta...
FAILED backend/tests/integration/api/internal/test_resilience_validation_endpoints.py::TestSecurityValidationEndpoints::test_security_validation_endpoint_valid_config - AssertionError: Valid configuration should pass validation check
FAILED backend/tests/integration/api/internal/test_resilience_validation_endpoints.py::TestSecurityValidationEndpoints::test_security_validation_large_config - assert False
FAILED backend/tests/integration/api/internal/test_resilience_validation_endpoints.py::TestSecurityValidationIntegration::test_security_validation_with_monitoring_integration - assert False is True
FAILED backend/tests/integration/api/v1/test_auth_endpoints.py::TestAuthenticationEdgeCases::test_auth_status_production_vs_development_mode - assert 429 in [200, 401]
FAILED backend/tests/integration/api/v1/test_auth_endpoints.py::TestAuthenticationEndpoints::test_auth_status_with_invalid_key_returns_401 - assert 200 == 401
FAILED backend/tests/integration/api/v1/test_auth_endpoints.py::TestAuthenticationIntegration::test_auth_status_development_mode_behavior - AssertionError: assert 'developm...' == 'development'
FAILED backend/tests/integration/api/v1/test_health_endpoint_scenarios.py::test_health_all_components_healthy - AssertionError: assert 'degraded' == 'healthy'
FAILED backend/tests/integration/api/v1/test_health_endpoint_scenarios.py::test_health_endpoint_graceful_failure - assert True is None
FAILED backend/tests/integration/api/v1/test_text_processing_endpoints.py::TestAuthentication::test_authenticated_client_fixture - assert 429 == 200
FAILED backend/tests/integration/api/v1/test_text_processing_endpoints.py::TestAuthentication::test_process_with_explicit_auth - app.core.exceptions.AuthenticationError: Invalid API key (Context: {'auth_method': 'bearer_token', 'environment': 'development', 'confidence': 0...
FAILED backend/tests/integration/api/v1/test_text_processing_endpoints.py::TestAuthentication::test_process_with_invalid_auth - pydantic_ai.exceptions.UserError: Set the `GOOGLE_API_KEY` environment variable or pass it via `GoogleProvider(api_key=...)`to use the Google Ge...
FAILED backend/tests/integration/api/v1/test_text_processing_endpoints.py::TestBatchProcessEndpoint::test_batch_process_empty_requests_list - assert 429 == 422
FAILED backend/tests/integration/api/v1/test_text_processing_endpoints.py::TestBatchProcessEndpoint::test_batch_process_exceeds_limit - app.core.exceptions.AuthenticationError: Invalid API key (Context: {'auth_method': 'bearer_token', 'environment': 'development', 'confidence': 0...
FAILED backend/tests/integration/api/v1/test_text_processing_endpoints.py::TestBatchProcessEndpoint::test_batch_process_invalid_auth - pydantic_ai.exceptions.UserError: Set the `GOOGLE_API_KEY` environment variable or pass it via `GoogleProvider(api_key=...)`to use the Google Ge...
FAILED backend/tests/integration/api/v1/test_text_processing_endpoints.py::TestBatchProcessEndpoint::test_batch_process_no_auth - pydantic_ai.exceptions.UserError: Set the `GOOGLE_API_KEY` environment variable or pass it via `GoogleProvider(api_key=...)`to use the Google Ge...
FAILED backend/tests/integration/api/v1/test_text_processing_endpoints.py::TestBatchProcessEndpoint::test_batch_process_service_exception - app.core.exceptions.AuthenticationError: Invalid API key (Context: {'auth_method': 'bearer_token', 'environment': 'development', 'confidence': 0...
FAILED backend/tests/integration/api/v1/test_text_processing_endpoints.py::TestBatchProcessEndpoint::test_batch_process_success - assert 429 == 200
FAILED backend/tests/integration/api/v1/test_text_processing_endpoints.py::TestBatchStatusEndpoint::test_get_batch_status_invalid_auth - assert 200 == 401
FAILED backend/tests/integration/api/v1/test_text_processing_endpoints.py::TestBatchStatusEndpoint::test_get_batch_status_no_auth - assert 200 == 401
FAILED backend/tests/integration/api/v1/test_text_processing_endpoints.py::TestCacheIntegration::test_process_with_cache_hit - assert 429 == 200
FAILED backend/tests/integration/api/v1/test_text_processing_endpoints.py::TestCacheIntegration::test_process_with_cache_miss - assert 429 == 200
FAILED backend/tests/integration/api/v1/test_text_processing_endpoints.py::TestProcessEndpoint::test_process_empty_text - assert 429 == 422
FAILED backend/tests/integration/api/v1/test_text_processing_endpoints.py::TestProcessEndpoint::test_process_invalid_operation - assert 429 == 422
FAILED backend/tests/integration/api/v1/test_text_processing_endpoints.py::TestProcessEndpoint::test_process_qa_with_question - assert 429 == 200
FAILED backend/tests/integration/api/v1/test_text_processing_endpoints.py::TestProcessEndpoint::test_process_qa_without_question - assert 429 in [400, 422]
FAILED backend/tests/integration/api/v1/test_text_processing_endpoints.py::TestProcessEndpoint::test_process_sentiment - assert 429 == 200
FAILED backend/tests/integration/api/v1/test_text_processing_endpoints.py::TestProcessEndpoint::test_process_summarize - assert 429 == 200
FAILED backend/tests/integration/api/v1/test_text_processing_endpoints.py::TestProcessEndpoint::test_process_text_too_long - app.core.exceptions.AuthenticationError: Invalid API key (Context: {'auth_method': 'bearer_token', 'environment': 'development', 'confidence': 0...
FAILED backend/tests/integration/auth/test_authentication_features.py::TestMultiKeyAuthenticationWithEnvironmentConfiguration::test_invalid_api_key_format_rejected - assert 200 == 401
FAILED backend/tests/integration/auth/test_authentication_features.py::TestMultiKeyAuthenticationWithEnvironmentConfiguration::test_mixed_case_authentication_mode_configuration - assert 429 == 200
FAILED backend/tests/integration/auth/test_concurrency.py::TestAuthenticationThreadSafetyAndPerformance::test_authentication_system_integrates_seamlessly_with_fastapi_asynchronous_request_handling - assert 429 == 200
FAILED backend/tests/integration/auth/test_concurrency.py::TestAuthenticationThreadSafetyAndPerformance::test_concurrent_authentication_requests_maintain_performance_under_load - assert 429 == 200
FAILED backend/tests/integration/auth/test_dependency_injection.py::TestFastAPIDependencyInjectionIntegration::test_authentication_dependency_interacts_correctly_with_fastapi_middleware_stack - assert 429 == 200
FAILED backend/tests/integration/auth/test_dependency_injection.py::TestFastAPIDependencyInjectionIntegration::test_authentication_metadata_correctly_injected_for_downstream_use - assert 429 == 200
FAILED backend/tests/integration/auth/test_dependency_injection.py::TestFastAPIDependencyInjectionIntegration::test_authentication_state_properly_isolated_between_concurrent_requests - assert 429 == 200
FAILED backend/tests/integration/auth/test_dependency_injection.py::TestFastAPIDependencyInjectionIntegration::test_authentication_successful_with_bearer_token_header - assert 429 == 200
FAILED backend/tests/integration/auth/test_dependency_injection.py::TestFastAPIDependencyInjectionIntegration::test_concurrent_requests_with_different_valid_keys_authenticated_successfully - assert 429 == 200
FAILED backend/tests/integration/auth/test_error_context.py::TestAuthenticationErrorContextAndDebugging::test_authentication_error_includes_details_on_credential_status_and_validation_failure - assert 200 == 401
FAILED backend/tests/integration/auth/test_error_context.py::TestAuthenticationErrorContextAndDebugging::test_authentication_errors_correctly_processed_by_global_exception_handling_and_logging_systems - assert 200 == 401
FAILED backend/tests/integration/auth/test_error_context.py::TestAuthenticationErrorContextAndDebugging::test_authentication_errors_logged_in_structured_format_for_security_monitoring - assert 200 == 401
FAILED backend/tests/integration/auth/test_error_context.py::TestAuthenticationErrorContextAndDebugging::test_authentication_failure_error_includes_environment_detection_context - assert 200 == 401
FAILED backend/tests/integration/auth/test_error_context.py::TestAuthenticationErrorContextAndDebugging::test_error_context_preserved_when_authentication_error_converted_to_http_exception - assert 200 == 401
FAILED backend/tests/integration/auth/test_http_exception_handling.py::TestHTTPExceptionConversionAndMiddlewareCompatibility::test_401_response_for_invalid_api_key_contains_original_error_context - assert 429 == 401
FAILED backend/tests/integration/auth/test_http_exception_handling.py::TestHTTPExceptionConversionAndMiddlewareCompatibility::test_401_response_includes_www_authenticate_header - assert 429 == 401
FAILED backend/tests/integration/auth/test_http_exception_handling.py::TestHTTPExceptionConversionAndMiddlewareCompatibility::test_api_clients_receive_structured_error_response_on_authentication_failure - assert 429 == 401
FAILED backend/tests/integration/auth/test_http_exception_handling.py::TestHTTPExceptionConversionAndMiddlewareCompatibility::test_authentication_errors_correctly_handled_by_global_exception_handler - assert 429 == 401
FAILED backend/tests/integration/auth/test_http_exception_handling.py::TestHTTPExceptionConversionAndMiddlewareCompatibility::test_authentication_errors_handled_consistently_without_middleware_conflicts - assert 429 == 401
FAILED backend/tests/integration/auth/test_http_exception_handling.py::TestHTTPExceptionConversionAndMiddlewareCompatibility::test_chained_exceptions_preserve_debugging_context_during_authentication_failures - assert 429 == 401
FAILED backend/tests/integration/auth/test_http_exception_handling.py::TestHTTPExceptionConversionAndMiddlewareCompatibility::test_error_response_for_authentication_failure_includes_environment_detection_information - assert 429 == 401
FAILED backend/tests/integration/auth/test_http_exception_handling.py::TestHTTPExceptionConversionAndMiddlewareCompatibility::test_invalid_api_key_receives_401_unauthorized_response - assert 429 == 401
FAILED backend/tests/integration/auth/test_http_exception_handling.py::TestHTTPExceptionConversionAndMiddlewareCompatibility::test_malformed_authentication_headers_return_401_with_validation_error - assert 200 == 401
FAILED backend/tests/integration/auth/test_http_exception_handling.py::TestHTTPExceptionConversionAndMiddlewareCompatibility::test_missing_credentials_return_401_with_appropriate_error_message - assert 200 == 401
FAILED backend/tests/integration/auth/test_status_api.py::TestAuthenticationStatusAPIIntegration::test_auth_status_response_differs_between_development_and_production_environments - assert 429 == 200
FAILED backend/tests/integration/auth/test_system_monitoring.py::TestAuthenticationSystemStatusAndMonitoring::test_auth_status_endpoint_reports_number_of_active_api_keys_without_exposing_them - assert 0 == 3
FAILED backend/tests/integration/auth/test_system_monitoring.py::TestAuthenticationSystemStatusAndMonitoring::test_concurrent_requests_to_status_endpoint_do_not_corrupt_status_information - assert 0 == 3
FAILED backend/tests/integration/environment/test_auth_api_environment_integration.py::TestAuthAPIEnvironmentIntegration::test_auth_status_environment_detection_confidence_reflection - assert 429 == 200
FAILED backend/tests/integration/environment/test_auth_api_environment_integration.py::TestAuthAPIEnvironmentIntegration::test_auth_status_performance_under_environment_detection - assert 429 == 200
FAILED backend/tests/integration/environment/test_auth_api_environment_integration.py::TestAuthAPIEnvironmentIntegration::test_auth_status_response_includes_environment_context - assert 429 == 200
FAILED backend/tests/integration/environment/test_auth_api_environment_integration.py::TestAuthAPIEnvironmentIntegration::test_auth_status_with_custom_environment_detection - assert 429 == 200
FAILED backend/tests/integration/environment/test_auth_api_environment_integration.py::TestAuthAPIEnvironmentIntegration::test_auth_status_with_environment_detection_failure - Failed: DID NOT RAISE <class 'Exception'>
FAILED backend/tests/integration/environment/test_auth_api_environment_integration.py::TestAuthAPIEnvironmentIntegration::test_auth_status_with_feature_specific_contexts - assert 429 == 200
FAILED backend/tests/integration/environment/test_cache_preset_integration.py::TestCachePresetEnvironmentIntegration::test_cache_preset_confidence_influence - AssertionError: assert 0.7999999999999999 < 0.7
FAILED backend/tests/integration/environment/test_cache_preset_integration.py::TestCachePresetEnvironmentIntegration::test_cache_preset_error_handling - Failed: DID NOT RAISE <class 'Exception'>
FAILED backend/tests/integration/environment/test_cache_preset_integration.py::TestCachePresetEnvironmentIntegration::test_cache_preset_with_unknown_environment - AssertionError: assert 0.7999999999999999 < 0.7
FAILED backend/tests/integration/environment/test_cache_preset_integration.py::TestCachePresetEnvironmentIntegration::test_staging_environment_recommends_balanced_cache_preset - AssertionError: assert ('staging' in 'production' or 'stage' in 'production')
FAILED backend/tests/integration/environment/test_confidence_fallback_system.py::TestEnvironmentDetectionConfidenceAndFallback::test_confidence_bounds_and_constraints - NameError: name 'os' is not defined. Did you forget to import 'os'?
FAILED backend/tests/integration/environment/test_confidence_fallback_system.py::TestEnvironmentDetectionConfidenceAndFallback::test_confidence_scoring_consistency - UnboundLocalError: cannot access local variable 'os' where it is not associated with a value
FAILED backend/tests/integration/environment/test_confidence_fallback_system.py::TestEnvironmentDetectionConfidenceAndFallback::test_conflicting_signals_reduce_confidence - NameError: name 'os' is not defined. Did you forget to import 'os'?
FAILED backend/tests/integration/environment/test_confidence_fallback_system.py::TestEnvironmentDetectionConfidenceAndFallback::test_detection_determinism - NameError: name 'os' is not defined. Did you forget to import 'os'?
FAILED backend/tests/integration/environment/test_confidence_fallback_system.py::TestEnvironmentDetectionConfidenceAndFallback::test_detection_performance_under_load - NameError: name 'os' is not defined. Did you forget to import 'os'?
FAILED backend/tests/integration/environment/test_confidence_fallback_system.py::TestEnvironmentDetectionConfidenceAndFallback::test_environment_variable_precedence_rules - NameError: name 'os' is not defined. Did you forget to import 'os'?
FAILED backend/tests/integration/environment/test_confidence_fallback_system.py::TestEnvironmentDetectionConfidenceAndFallback::test_fallback_to_development_with_no_signals - AssertionError: assert 0.75 < 0.7
FAILED backend/tests/integration/environment/test_confidence_fallback_system.py::TestEnvironmentDetectionConfidenceAndFallback::test_multiple_agreeing_signals_boost_confidence - NameError: name 'os' is not defined. Did you forget to import 'os'?
FAILED backend/tests/integration/environment/test_confidence_fallback_system.py::TestEnvironmentDetectionConfidenceAndFallback::test_pattern_based_detection_with_hostname - AssertionError: assert <Environment....'development'> == <Environment.... 'production'>
FAILED backend/tests/integration/environment/test_confidence_fallback_system.py::TestEnvironmentDetectionConfidenceAndFallback::test_reasoning_comprehensiveness - NameError: name 'os' is not defined. Did you forget to import 'os'?
FAILED backend/tests/integration/environment/test_confidence_fallback_system.py::TestEnvironmentDetectionConfidenceAndFallback::test_signal_collection_completeness - NameError: name 'os' is not defined. Did you forget to import 'os'?
FAILED backend/tests/integration/environment/test_detection_performance_caching.py::TestEnvironmentDetectionPerformanceAndCaching::test_environment_detection_with_custom_configuration_performance - AssertionError: assert None is True
FAILED backend/tests/integration/environment/test_end_to_end_validation.py::TestEndToEndEnvironmentValidation::test_environment_detection_error_handling_end_to_end - AttributeError: module 'pytest' has no attribute 'mock'
FAILED backend/tests/integration/environment/test_end_to_end_validation.py::TestEndToEndEnvironmentValidation::test_environment_detection_with_system_indicators_end_to_end - KeyError: 'ENVIRONMENT'
FAILED backend/tests/integration/environment/test_end_to_end_validation.py::TestEndToEndEnvironmentValidation::test_environment_feature_context_end_to_end - AssertionError: assert <Environment....'development'> == <Environment.... 'production'>
FAILED backend/tests/integration/environment/test_end_to_end_validation.py::TestEndToEndEnvironmentValidation::test_environment_variable_development_allows_flexible_security - AssertionError: assert False is True
FAILED backend/tests/integration/environment/test_end_to_end_validation.py::TestEndToEndEnvironmentValidation::test_environment_variable_precedence_end_to_end - AssertionError: assert 0.8075 >= 0.9
FAILED backend/tests/integration/environment/test_end_to_end_validation.py::TestEndToEndEnvironmentValidation::test_environment_variable_staging_balanced_security - Failed: DID NOT RAISE <class 'app.core.exceptions.ConfigurationError'>
FAILED backend/tests/integration/environment/test_multi_context_detection.py::TestMultiContextEnvironmentDetection::test_ai_enabled_context_provides_cache_metadata - assert 0 >= 1
FAILED backend/tests/integration/environment/test_multi_context_detection.py::TestMultiContextEnvironmentDetection::test_context_consistency_across_environments - NameError: name 'os' is not defined. Did you forget to import 'os'?
FAILED backend/tests/integration/environment/test_multi_context_detection.py::TestMultiContextEnvironmentDetection::test_context_metadata_format_consistency - AssertionError: assert 'feature_context' in {}
FAILED backend/tests/integration/environment/test_multi_context_detection.py::TestMultiContextEnvironmentDetection::test_context_reasoning_comprehensiveness - AssertionError: assert ('security' in 'development indicator detected: .env (confirmed by 2 additional signals)' or 'enforcement' in 'developmen...
FAILED backend/tests/integration/environment/test_multi_context_detection.py::TestMultiContextEnvironmentDetection::test_context_signal_collection_completeness - assert 0 >= 1
FAILED backend/tests/integration/environment/test_multi_context_detection.py::TestMultiContextEnvironmentDetection::test_context_with_custom_configuration - NameError: name 'os' is not defined. Did you forget to import 'os'?
FAILED backend/tests/integration/environment/test_multi_context_detection.py::TestMultiContextEnvironmentDetection::test_default_context_consistency - AssertionError: assert 'feature_context' in {}
FAILED backend/tests/integration/environment/test_multi_context_detection.py::TestMultiContextEnvironmentDetection::test_security_enforcement_context_applies_overrides - AssertionError: assert <Environment....'development'> == <Environment.... 'production'>
FAILED backend/tests/integration/environment/test_resilience_preset_integration.py::TestResiliencePresetEnvironmentIntegration::test_resilience_preset_confidence_influence - AssertionError: assert 0.7999999999999999 < 0.7
FAILED backend/tests/integration/environment/test_resilience_preset_integration.py::TestResiliencePresetEnvironmentIntegration::test_resilience_preset_error_handling - Failed: DID NOT RAISE <class 'Exception'>
FAILED backend/tests/integration/environment/test_resilience_preset_integration.py::TestResiliencePresetEnvironmentIntegration::test_resilience_preset_with_unknown_environment - AssertionError: assert 0.7999999999999999 < 0.7
FAILED backend/tests/integration/environment/test_security_environment_enforcement.py::TestSecurityEnvironmentEnforcement::test_ai_context_in_production_with_security_requirements - Failed: DID NOT RAISE <class 'app.core.exceptions.ConfigurationError'>
FAILED backend/tests/integration/environment/test_security_environment_enforcement.py::TestSecurityEnvironmentEnforcement::test_authentication_status_endpoint_environment_awareness - Failed: DID NOT RAISE <class 'Exception'>
FAILED backend/tests/integration/environment/test_security_environment_enforcement.py::TestSecurityEnvironmentEnforcement::test_development_environment_allows_no_api_keys - AssertionError: assert False is True
FAILED backend/tests/integration/environment/test_security_environment_enforcement.py::TestSecurityEnvironmentEnforcement::test_environment_detection_failure_defaults_to_secure_mode - NameError: name 'os' is not defined. Did you forget to import 'os'?
FAILED backend/tests/integration/environment/test_security_environment_enforcement.py::TestSecurityEnvironmentEnforcement::test_environment_detection_service_availability - Failed: DID NOT RAISE <class 'Exception'>
FAILED backend/tests/integration/environment/test_security_environment_enforcement.py::TestSecurityEnvironmentEnforcement::test_environment_detection_with_mixed_signals - NameError: name 'os' is not defined. Did you forget to import 'os'?
FAILED backend/tests/integration/environment/test_security_environment_enforcement.py::TestSecurityEnvironmentEnforcement::test_production_environment_enforces_api_keys - Failed: DID NOT RAISE <class 'app.core.exceptions.ConfigurationError'>
FAILED backend/tests/integration/environment/test_security_environment_enforcement.py::TestSecurityEnvironmentEnforcement::test_security_enforcement_context_overrides_to_production - AssertionError: assert <Environment....'development'> == <Environment.... 'production'>
FAILED backend/tests/integration/health/test_health_api_integration.py::TestHealthMonitoringAPIIntegration::test_health_monitoring_api_error_handling_and_response_format - AttributeError: <module 'app.api.internal.monitoring' from '/Users/matth/Github/MGH/fastapi-streamlit-llm-starter/backend/app/api/internal/monit...
FAILED backend/tests/integration/health/test_health_api_integration.py::TestHealthMonitoringAPIIntegration::test_health_monitoring_api_with_mixed_component_health_states - AttributeError: 'method' object has no attribute 'return_value' and no __dict__ for setting new attributes
FAILED backend/tests/integration/resilience/test_circuit_breaker_recovery.py::TestCircuitBreakerRecovery::test_automatic_recovery_timeout_mechanism - AttributeError: 'EnhancedCircuitBreaker' object has no attribute 'record_failure'
FAILED backend/tests/integration/resilience/test_circuit_breaker_recovery.py::TestCircuitBreakerRecovery::test_circuit_breaker_metrics_tracking - AttributeError: 'EnhancedCircuitBreaker' object has no attribute 'record_failure'
FAILED backend/tests/integration/resilience/test_circuit_breaker_recovery.py::TestCircuitBreakerRecovery::test_circuit_breaker_state_persistence - AttributeError: 'EnhancedCircuitBreaker' object has no attribute 'record_failure'
FAILED backend/tests/integration/resilience/test_circuit_breaker_recovery.py::TestCircuitBreakerRecovery::test_circuit_breaker_state_transitions_complete_cycle - AttributeError: 'EnhancedCircuitBreaker' object has no attribute 'get_health_status'
FAILED backend/tests/integration/resilience/test_circuit_breaker_recovery.py::TestCircuitBreakerRecovery::test_concurrent_circuit_breaker_access - AttributeError: 'EnhancedCircuitBreaker' object has no attribute 'record_failure'
FAILED backend/tests/integration/resilience/test_circuit_breaker_recovery.py::TestCircuitBreakerRecovery::test_health_check_reporting_accuracy - AttributeError: 'EnhancedCircuitBreaker' object has no attribute 'get_health_status'
FAILED backend/tests/integration/resilience/test_circuit_breaker_recovery.py::TestCircuitBreakerRecovery::test_health_endpoint_integration - assert 0 == 2
FAILED backend/tests/integration/resilience/test_circuit_breaker_recovery.py::TestCircuitBreakerRecovery::test_multiple_operations_isolated_circuit_breakers - AttributeError: 'EnhancedCircuitBreaker' object has no attribute 'record_failure'
FAILED backend/tests/integration/resilience/test_configuration_environment_selection.py::TestConfigurationEnvironmentSelection::test_auto_environment_detection - AttributeError: 'EnvironmentRecommendation' object has no attribute 'preset'
FAILED backend/tests/integration/resilience/test_configuration_environment_selection.py::TestConfigurationEnvironmentSelection::test_configuration_error_handling - AssertionError: Regex pattern did not match.
FAILED backend/tests/integration/resilience/test_configuration_environment_selection.py::TestConfigurationEnvironmentSelection::test_configuration_validation - AssertionError: assert -1 >= 1
FAILED backend/tests/integration/resilience/test_configuration_environment_selection.py::TestConfigurationEnvironmentSelection::test_environment_detection_development - AttributeError: 'EnvironmentRecommendation' object has no attribute 'preset'
FAILED backend/tests/integration/resilience/test_configuration_environment_selection.py::TestConfigurationEnvironmentSelection::test_environment_detection_production - AttributeError: 'EnvironmentRecommendation' object has no attribute 'preset'
FAILED backend/tests/integration/resilience/test_configuration_environment_selection.py::TestConfigurationEnvironmentSelection::test_environment_pattern_matching - AttributeError: 'EnvironmentRecommendation' object has no attribute 'preset'
FAILED backend/tests/integration/resilience/test_configuration_environment_selection.py::TestConfigurationEnvironmentSelection::test_environment_recommendation_confidence_scoring - AssertionError: assert ('exact' in 'explicit environment from environment=production (note: 3 conflicting signals detected)' or 'direct' in 'exp...
FAILED backend/tests/integration/resilience/test_configuration_environment_selection.py::TestConfigurationEnvironmentSelection::test_preset_details_and_metadata - AssertionError: assert 'retry_attempts' in {'configuration': {'circuit_breaker_threshold': 5, 'default_strategy': 'balanced', 'operation_overrid...
FAILED backend/tests/integration/resilience/test_configuration_environment_selection.py::TestConfigurationEnvironmentSelection::test_resilience_service_configuration_integration - AssertionError: assert (<ResilienceStrategy.BALANCED: 'balanced'> != <ResilienceStrategy.BALANCED: 'balanced'> or ResilienceConfig(strategy=<Res...
FAILED backend/tests/integration/resilience/test_configuration_environment_selection.py::TestConfigurationEnvironmentSelection::test_strategy_enum_validation - AssertionError: assert 'ResilienceStrategy.BALANCED' == 'balanced'
FAILED backend/tests/integration/resilience/test_configuration_migration_validation.py::TestConfigurationMigrationValidation::test_configuration_change_detection - AttributeError: 'ConfigurationMetricsCollector' object has no attribute 'record_configuration_change'. Did you mean: 'record_config_change'?
FAILED backend/tests/integration/resilience/test_configuration_migration_validation.py::TestConfigurationMigrationValidation::test_configuration_migration_execution - AttributeError: 'ConfigurationMigrator' object has no attribute 'migrate_config'
FAILED backend/tests/integration/resilience/test_configuration_migration_validation.py::TestConfigurationMigrationValidation::test_configuration_performance_optimization - AttributeError: 'ConfigurationMigrator' object has no attribute 'analyze_performance_impact'
FAILED backend/tests/integration/resilience/test_configuration_migration_validation.py::TestConfigurationMigrationValidation::test_configuration_validation_comprehensive - AttributeError: 'ConfigurationMigrator' object has no attribute 'validate_migrated_config'
FAILED backend/tests/integration/resilience/test_configuration_migration_validation.py::TestConfigurationMigrationValidation::test_configuration_validation_security_checks - AttributeError: 'ConfigurationMigrator' object has no attribute 'validate_migrated_config'
FAILED backend/tests/integration/resilience/test_configuration_migration_validation.py::TestConfigurationMigrationValidation::test_legacy_configuration_analysis - AttributeError: 'LegacyConfigAnalyzer' object has no attribute 'analyze_legacy_config'
FAILED backend/tests/integration/resilience/test_configuration_migration_validation.py::TestConfigurationMigrationValidation::test_migration_comprehensive_integration - AttributeError: 'LegacyConfigAnalyzer' object has no attribute 'analyze_legacy_config'
FAILED backend/tests/integration/resilience/test_configuration_migration_validation.py::TestConfigurationMigrationValidation::test_migration_confidence_scoring - AttributeError: 'LegacyConfigAnalyzer' object has no attribute 'analyze_legacy_config'
FAILED backend/tests/integration/resilience/test_configuration_migration_validation.py::TestConfigurationMigrationValidation::test_migration_monitoring_and_audit_trails - AttributeError: 'ConfigurationMetricsCollector' object has no attribute 'record_migration_event'. Did you mean: 'record_validation_event'?
FAILED backend/tests/integration/resilience/test_configuration_migration_validation.py::TestConfigurationMigrationValidation::test_migration_rollback_capabilities - AttributeError: 'ConfigurationMetricsCollector' object has no attribute 'record_configuration_change'. Did you mean: 'record_config_change'?
FAILED backend/tests/integration/resilience/test_exception_handling_fallback.py::TestExceptionHandlingFallback::test_exception_classification_accuracy - AttributeError: 'Outcome' object has no attribute 'failed'
FAILED backend/tests/integration/resilience/test_exception_handling_fallback.py::TestExceptionHandlingFallback::test_exception_classification_edge_cases - assert False is True
FAILED backend/tests/integration/resilience/test_exception_handling_fallback.py::TestExceptionHandlingFallback::test_exception_context_preservation - assert 0 > 0
FAILED backend/tests/integration/resilience/test_exception_handling_fallback.py::TestExceptionHandlingFallback::test_fallback_execution_on_retry_exhaustion - assert False is True
FAILED backend/tests/integration/resilience/test_exception_handling_fallback.py::TestExceptionHandlingFallback::test_fallback_preserves_request_context - AssertionError: assert None == {'metadata': {'priority': 'high', 'user_id': 'user123'}, 'operation': 'summarize', 'options': {'format': 'paragra...
FAILED backend/tests/integration/resilience/test_exception_handling_fallback.py::TestExceptionHandlingFallback::test_graceful_degradation_patterns - assert False
FAILED backend/tests/integration/resilience/test_exception_handling_fallback.py::TestExceptionHandlingFallback::test_permanent_error_fail_fast - Failed: DID NOT RAISE <class 'app.core.exceptions.PermanentAIError'>
FAILED backend/tests/integration/resilience/test_exception_handling_fallback.py::TestExceptionHandlingFallback::test_rate_limit_error_retry_with_backoff - AssertionError: assert <coroutine object TestExceptionHandlingFallback.test_rate_limit_error_retry_with_backoff.<locals>.rate_limited_operation ...
FAILED backend/tests/integration/resilience/test_exception_handling_fallback.py::TestExceptionHandlingFallback::test_transient_error_retry_success - AssertionError: assert <coroutine object TestExceptionHandlingFallback.test_transient_error_retry_success.<locals>.unreliable_operation at 0x126...
FAILED backend/tests/integration/test_request_isolation.py::TestContextIsolation::test_batch_processing_isolation - assert 429 == 200
FAILED backend/tests/integration/test_request_isolation.py::TestContextIsolation::test_cache_isolation_by_content - app.core.exceptions.InfrastructureError: Failed to process text (Context: {'operation': 'summarize', 'request_id': '2a0135b6-bfe7-4ab9-a108-9d63...
FAILED backend/tests/integration/test_request_isolation.py::TestContextIsolation::test_concurrent_requests_isolation - app.core.exceptions.InfrastructureError: Failed to process text (Context: {'operation': 'summarize', 'request_id': '27f022d1-e92a-4508-829c-d388...
FAILED backend/tests/integration/test_request_isolation.py::TestContextIsolation::test_different_operations_isolation - app.core.exceptions.InfrastructureError: Failed to process text (Context: {'operation': 'sentiment', 'request_id': '2a857e0e-8651-4b67-817f-cad0...
FAILED backend/tests/integration/test_request_isolation.py::TestContextIsolation::test_error_handling_isolation - assert 429 == 200
FAILED backend/tests/integration/test_request_isolation.py::TestContextIsolation::test_injection_attempt_isolation - assert 429 == 200
FAILED backend/tests/integration/test_request_isolation.py::TestContextIsolation::test_qa_operation_isolation - app.core.exceptions.InfrastructureError: Failed to process text (Context: {'operation': 'qa', 'request_id': '26318db8-3516-47b2-8970-a4ffdb09316...
FAILED backend/tests/integration/test_request_isolation.py::TestContextIsolation::test_sequential_requests_no_context_leakage - app.core.exceptions.InfrastructureError: Failed to process text (Context: {'operation': 'summarize', 'request_id': '897ca12a-d9e1-4f0a-aa1a-a85b...
FAILED backend/tests/integration/test_request_isolation.py::TestRequestBoundaryLogging::test_processing_boundary_logging - assert 429 == 200
FAILED backend/tests/integration/test_request_isolation.py::TestRequestBoundaryLogging::test_request_boundary_logging_format - app.core.exceptions.InfrastructureError: Failed to process text (Context: {'operation': 'summarize', 'request_id': 'b2ab36bb-d190-45c4-b4dc-68c2...
FAILED backend/tests/integration/test_request_isolation.py::TestRequestBoundaryLogging::test_unique_request_ids - assert 429 == 200
FAILED backend/tests/integration/text_processor/test_cache_integration.py::TestCacheIntegration::test_cache_compression_integration - app.core.exceptions.AuthenticationError: Invalid API key (Context: {'auth_method': 'bearer_token', 'environment': 'development', 'confidence': 0...
FAILED backend/tests/integration/text_processor/test_cache_integration.py::TestCacheIntegration::test_cache_failure_fallback - app.core.exceptions.AuthenticationError: Invalid API key (Context: {'auth_method': 'bearer_token', 'environment': 'development', 'confidence': 0...
FAILED backend/tests/integration/text_processor/test_cache_integration.py::TestCacheIntegration::test_cache_hit_scenario - app.core.exceptions.AuthenticationError: Invalid API key (Context: {'auth_method': 'bearer_token', 'environment': 'development', 'confidence': 0...
FAILED backend/tests/integration/text_processor/test_cache_integration.py::TestCacheIntegration::test_cache_invalidation_integration - app.core.exceptions.AuthenticationError: Invalid API key (Context: {'auth_method': 'bearer_token', 'environment': 'development', 'confidence': 0...
FAILED backend/tests/integration/text_processor/test_cache_integration.py::TestCacheIntegration::test_cache_key_generation_uniqueness - app.core.exceptions.AuthenticationError: Invalid API key (Context: {'auth_method': 'bearer_token', 'environment': 'development', 'confidence': 0...
FAILED backend/tests/integration/text_processor/test_cache_integration.py::TestCacheIntegration::test_cache_memory_usage_monitoring - assert 429 == 200
FAILED backend/tests/integration/text_processor/test_cache_integration.py::TestCacheIntegration::test_cache_miss_scenario - app.core.exceptions.AuthenticationError: Invalid API key (Context: {'auth_method': 'bearer_token', 'environment': 'development', 'confidence': 0...
FAILED backend/tests/integration/text_processor/test_cache_integration.py::TestCacheIntegration::test_cache_performance_monitoring_integration - app.core.exceptions.AuthenticationError: Invalid API key (Context: {'auth_method': 'bearer_token', 'environment': 'development', 'confidence': 0...
FAILED backend/tests/integration/text_processor/test_cache_integration.py::TestCacheIntegration::test_cache_with_different_operations - app.core.exceptions.AuthenticationError: Invalid API key (Context: {'auth_method': 'bearer_token', 'environment': 'development', 'confidence': 0...
FAILED backend/tests/integration/text_processor/test_cache_integration.py::TestCacheIntegration::test_concurrent_cache_access_safety - app.core.exceptions.AuthenticationError: Invalid API key (Context: {'auth_method': 'bearer_token', 'environment': 'development', 'confidence': 0...
FAILED backend/tests/integration/text_processor/test_complete_text_processing_flow.py::TestCompleteTextProcessingFlow::test_complete_text_processing_pipeline_success - assert 429 == 200
FAILED backend/tests/integration/text_processor/test_complete_text_processing_flow.py::TestCompleteTextProcessingFlow::test_pipeline_request_tracing_integration - app.core.exceptions.InfrastructureError: Failed to process text (Context: {'operation': 'key_points', 'request_id': '646ac9bd-a2b8-42c1-b1a0-156...
FAILED backend/tests/integration/text_processor/test_complete_text_processing_flow.py::TestCompleteTextProcessingFlow::test_pipeline_with_authentication_integration - app.core.exceptions.InfrastructureError: Failed to process text (Context: {'operation': 'sentiment', 'request_id': '412a8256-71d2-43d1-b3da-935f...
FAILED backend/tests/integration/text_processor/test_complete_text_processing_flow.py::TestCompleteTextProcessingFlow::test_pipeline_with_caching_integration - app.core.exceptions.InfrastructureError: Failed to process text (Context: {'operation': 'summarize', 'request_id': '33403580-d9fc-4b7a-8c5b-c575...
FAILED backend/tests/integration/text_processor/test_complete_text_processing_flow.py::TestCompleteTextProcessingFlow::test_pipeline_with_different_operations - assert 429 == 200
FAILED backend/tests/integration/text_processor/test_complete_text_processing_flow.py::TestCompleteTextProcessingFlow::test_pipeline_with_infrastructure_errors - app.core.exceptions.InfrastructureError: Failed to process text (Context: {'operation': 'summarize', 'request_id': '251453a4-97d7-44ed-a9db-618c...
FAILED backend/tests/integration/text_processor/test_complete_text_processing_flow.py::TestCompleteTextProcessingFlow::test_pipeline_with_input_sanitization - app.core.exceptions.InfrastructureError: Failed to process text (Context: {'operation': 'summarize', 'request_id': 'c8ab759c-f8aa-4083-b3e8-d563...
FAILED backend/tests/integration/text_processor/test_complete_text_processing_flow.py::TestCompleteTextProcessingFlow::test_pipeline_with_resilience_patterns - app.core.exceptions.InfrastructureError: Failed to process text (Context: {'operation': 'summarize', 'request_id': '557aa2c8-7422-482d-aaac-3cff...
FAILED backend/tests/integration/text_processor/test_complete_text_processing_flow.py::TestCompleteTextProcessingFlow::test_pipeline_with_validation_errors - NameError: name 'sample_text' is not defined
FAILED backend/tests/integration/text_processor/test_configuration_management.py::TestConfigurationManagement::test_configuration_migration_compatibility - assert 429 == 200
FAILED backend/tests/integration/text_processor/test_configuration_management.py::TestConfigurationManagement::test_configuration_monitoring_and_metrics - assert 429 == 200
FAILED backend/tests/integration/text_processor/test_configuration_management.py::TestConfigurationManagement::test_configuration_precedence_rules - assert 429 == 200
FAILED backend/tests/integration/text_processor/test_configuration_management.py::TestConfigurationManagement::test_configuration_validation_and_error_handling - Failed: DID NOT RAISE any of (<class 'app.core.exceptions.ConfigurationError'>, <class 'ValueError'>)
FAILED backend/tests/integration/text_processor/test_configuration_management.py::TestConfigurationManagement::test_custom_configuration_overrides - assert 429 == 200
FAILED backend/tests/integration/text_processor/test_configuration_management.py::TestConfigurationManagement::test_development_environment_configuration - assert 429 == 200
FAILED backend/tests/integration/text_processor/test_configuration_management.py::TestConfigurationManagement::test_dynamic_configuration_updates - assert 429 == 200
FAILED backend/tests/integration/text_processor/test_configuration_management.py::TestConfigurationManagement::test_operation_specific_strategy_selection - assert 429 == 200
FAILED backend/tests/integration/text_processor/test_configuration_management.py::TestConfigurationManagement::test_production_environment_configuration - assert 429 == 200
FAILED backend/tests/integration/text_processor/test_exception_handling_graceful_degradation.py::TestExceptionHandlingGracefulDegradation::test_error_recovery_and_system_resilience - app.core.exceptions.AuthenticationError: Invalid API key (Context: {'auth_method': 'bearer_token', 'environment': 'development', 'confidence': 0...
FAILED backend/tests/integration/text_processor/test_exception_handling_graceful_degradation.py::TestExceptionHandlingGracefulDegradation::test_exception_chaining_and_logging - app.core.exceptions.AuthenticationError: Invalid API key (Context: {'auth_method': 'bearer_token', 'environment': 'development', 'confidence': 0...
FAILED backend/tests/integration/text_processor/test_exception_handling_graceful_degradation.py::TestExceptionHandlingGracefulDegradation::test_graceful_degradation_under_load - app.core.exceptions.AuthenticationError: Invalid API key (Context: {'auth_method': 'bearer_token', 'environment': 'development', 'confidence': 0...
FAILED backend/tests/integration/text_processor/test_exception_handling_graceful_degradation.py::TestExceptionHandlingGracefulDegradation::test_network_timeout_handling - app.core.exceptions.AuthenticationError: Invalid API key (Context: {'auth_method': 'bearer_token', 'environment': 'development', 'confidence': 0...
FAILED backend/tests/integration/text_processor/test_exception_handling_graceful_degradation.py::TestExceptionHandlingGracefulDegradation::test_permanent_failure_immediate_fallback - app.core.exceptions.AuthenticationError: Invalid API key (Context: {'auth_method': 'bearer_token', 'environment': 'development', 'confidence': 0...
FAILED backend/tests/integration/text_processor/test_exception_handling_graceful_degradation.py::TestExceptionHandlingGracefulDegradation::test_retry_exhaustion_handling - app.core.exceptions.AuthenticationError: Invalid API key (Context: {'auth_method': 'bearer_token', 'environment': 'development', 'confidence': 0...
FAILED backend/tests/integration/text_processor/test_health_checks_monitoring.py::TestHealthChecksMonitoring::test_health_check_security_and_authentication - NameError: name 'auth_headers' is not defined
FAILED backend/tests/integration/text_processor/test_health_checks_monitoring.py::TestHealthChecksMonitoring::test_health_monitoring_under_load - app.core.exceptions.InfrastructureError: Failed to process text (Context: {'operation': 'summarize', 'request_id': '2f30c67a-51bd-47a0-98a2-6f37...
FAILED backend/tests/integration/text_processor/test_health_checks_monitoring.py::TestHealthChecksMonitoring::test_performance_metrics_integration - app.core.exceptions.InfrastructureError: Failed to process text (Context: {'operation': 'summarize', 'request_id': '982e9853-a889-4458-85ef-84b6...
FAILED backend/tests/performance/test_performance_benchmarks.py::TestBenchmarkIntegration::test_global_benchmark_instance - assert False
FAILED backend/tests/unit/api/v1/test_main_endpoints.py::TestHealthEndpoint::test_health_check - AssertionError: assert 'degraded' == 'healthy'
FAILED backend/tests/unit/core/middleware/test_global_exception_handler_middleware.py::TestGlobalExceptionHandler::test_business_logic_error_handling - AssertionError: Expected 'error' to have been called.
FAILED backend/tests/unit/core/middleware/test_global_exception_handler_middleware.py::TestGlobalExceptionHandler::test_generic_exception_handling - AssertionError: Expected 'error' to have been called.
FAILED backend/tests/unit/core/middleware/test_performance_monitoring_middleware.py::TestPerformanceMonitoringMiddleware::test_error_request_performance_logging - AssertionError: Expected 'error' to have been called.
FAILED backend/tests/unit/core/middleware/test_performance_monitoring_middleware.py::TestPerformanceMonitoringMiddleware::test_slow_request_threshold_boundary - AssertionError: Expected 'warning' to have been called.
FAILED backend/tests/unit/core/middleware/test_request_logging_middleware.py::TestRequestLoggingMiddleware::test_response_size_logging - assert None is not None
FAILED backend/tests/unit/core/middleware/test_utils.py::TestMiddlewareUtilities::test_get_request_duration_valid - assert None == 2500.0
FAILED backend/tests/unit/core/middleware/test_utils.py::TestMiddlewareUtilities::test_get_request_id_from_context - AssertionError: assert 'unknown' == 'context-request-456'
FAILED backend/tests/unit/core/test_dependencies.py::TestDependencyInjection::test_cache_service_uses_settings_redis_url - AssertionError: Expected 'AIResponseCache' to be called once. Called 0 times.
FAILED backend/tests/unit/core/test_dependencies.py::TestDependencyInjection::test_dependency_chain_integration - AssertionError: assert <app.infrastructure.cache.memory.InMemoryCache object at 0x10b37f800> is <MagicMock name='AIResponseCache()' spec='AIResp...
FAILED backend/tests/unit/core/test_dependencies.py::TestDependencyInjection::test_get_cache_service_creates_configured_instance - AssertionError: Expected 'AIResponseCache' to be called once. Called 0 times.
FAILED backend/tests/unit/core/test_dependencies.py::TestDependencyInjection::test_get_cache_service_graceful_degradation_when_redis_unavailable - AssertionError: Expected 'AIResponseCache' to be called once. Called 0 times.
FAILED backend/tests/unit/core/test_dependencies.py::TestDependencyInjection::test_get_cache_service_real_integration_with_unavailable_redis - assert False
FAILED backend/tests/unit/core/test_dependencies.py::TestDependencyInjection::test_get_cache_service_when_connect_raises_exception - AssertionError: Expected 'connect' to have been called once. Called 0 times.
FAILED backend/tests/unit/core/test_dependencies.py::TestDependencyInjection::test_get_text_processor_with_dependency_injection - AssertionError: assert <app.infrastructure.cache.memory.InMemoryCache object at 0x10b37f920> is <MagicMock name='AIResponseCache()' spec='AIResp...
FAILED backend/tests/unit/infrastructure/cache/cache_presets/test_cache_presets_manager.py::TestCachePresetManagerRecommendation::test_cache_preset_manager_handles_ambiguous_environment_scenarios - AssertionError: No environment signals should use safe fallback
FAILED backend/tests/unit/infrastructure/cache/config/test_config_builder.py::TestCacheConfigBuilderBuildAndValidation::test_build_method_creates_validated_cache_config_from_builder_state - AssertionError: assert False
FAILED backend/tests/unit/infrastructure/cache/config/test_config_builder.py::TestCacheConfigBuilderBuildAndValidation::test_validate_method_provides_comprehensive_builder_validation - assert False
FAILED backend/tests/unit/infrastructure/cache/factory/test_factory.py::TestAIApplicationCacheCreation::test_for_ai_app_handles_redis_connection_failure_with_fallback - AssertionError: assert False
FAILED backend/tests/unit/infrastructure/cache/factory/test_factory.py::TestTestingCacheCreation::test_for_testing_creates_cache_with_test_optimizations - AssertionError: assert False
FAILED backend/tests/unit/infrastructure/cache/factory/test_factory.py::TestTestingCacheCreation::test_for_testing_creates_memory_cache_when_requested - AssertionError: assert False
FAILED backend/tests/unit/infrastructure/cache/factory/test_factory.py::TestTestingCacheCreation::test_for_testing_supports_custom_test_database - AssertionError: assert False
FAILED backend/tests/unit/infrastructure/cache/redis_ai/test_redis_ai_inheritance.py::TestAIResponseCacheInheritance::test_init_properly_initializes_parent_class_with_mapped_parameters - AssertionError: AIResponseCache must inherit from GenericRedisCache
FAILED backend/tests/unit/infrastructure/cache/security/test_security_manager.py::TestRedisCacheSecurityManagerConnection::test_connection_authentication_failure_handled_gracefully - assert ('WRONGPASS' in "Error Multiple exceptions: [Errno 61] Connect call failed ('::1', 6379, 0, 0), [Errno 61] Connect call failed ('127.0.0....
FAILED backend/tests/unit/infrastructure/cache/security/test_security_manager.py::TestRedisCacheSecurityManagerConnection::test_connection_timeout_prevents_infinite_retry_loops - assert ('Connection timed out' in "Error Multiple exceptions: [Errno 61] Connect call failed ('::1', 6379, 0, 0), [Errno 61] Connect call failed...
FAILED backend/tests/unit/infrastructure/cache/security/test_security_manager.py::TestRedisCacheSecurityManagerConnection::test_create_secure_connection_establishes_connection_with_basic_auth - redis.exceptions.ConnectionError: Error Multiple exceptions: [Errno 61] Connect call failed ('::1', 6379, 0, 0), [Errno 61] Connect call failed ...
FAILED backend/tests/unit/infrastructure/cache/security/test_security_manager.py::TestRedisCacheSecurityManagerConnection::test_create_secure_connection_establishes_tls_encrypted_connection - TypeError: AbstractConnection.__init__() got an unexpected keyword argument 'ssl'
FAILED backend/tests/unit/infrastructure/cache/security/test_security_manager.py::TestRedisCacheSecurityManagerReporting::test_test_security_configuration_validates_end_to_end_security - assert False is True
FAILED backend/tests/unit/infrastructure/monitoring/test_health_engine.py::test_check_cache_health_paths - assert <HealthStatus.UNHEALTHY: 'unhealthy'> in {<HealthStatus.DEGRADED: 'degraded'>, <HealthStatus.HEALTHY: 'healthy'>}
FAILED backend/tests/unit/infrastructure/resilience/test_env_recommendations.py::TestEnvironmentRecommendationIntegration::test_all_recommendations_return_valid_presets - AttributeError: 'NoneType' object has no attribute 'lower'
FAILED backend/tests/unit/infrastructure/resilience/test_env_recommendations.py::TestEnvironmentRecommendations::test_auto_detection_development_indicators - AssertionError: assert 'development indicators detected' in 'development indicator detected: debug=true (confirmed by 3 additional signals)'
FAILED backend/tests/unit/infrastructure/resilience/test_env_recommendations.py::TestEnvironmentRecommendations::test_auto_detection_fallback_to_simple - AttributeError: 'NoneType' object has no attribute 'lower'
FAILED backend/tests/unit/infrastructure/resilience/test_env_recommendations.py::TestEnvironmentRecommendations::test_auto_detection_from_environment_variables - AttributeError: 'NoneType' object has no attribute 'lower'
FAILED backend/tests/unit/infrastructure/resilience/test_env_recommendations.py::TestEnvironmentRecommendations::test_auto_detection_production_indicators - AssertionError: assert 'production indicators detected' in 'production indicator detected: production=true (confirmed by 1 additional signals) (...
FAILED backend/tests/unit/infrastructure/resilience/test_resilience.py::TestCircuitBreakerStateTransitionLogging::test_circuit_breaker_state_check_method - AssertionError: Should have logged closed state
FAILED backend/tests/unit/infrastructure/resilience/test_resilience.py::TestConvenienceDecorators::test_all_convenience_decorators_work - AssertionError: assert 'aggressive_conv_test' in {}
FAILED backend/tests/unit/infrastructure/resilience/test_resilience.py::TestRetryLogic::test_should_retry_on_exception_function - AssertionError: assert True is False
FAILED backend/tests/unit/infrastructure/resilience/test_validation_schemas.py::TestConfigValidatorIntegration::test_settings_validate_custom_config - AttributeError: 'Settings' object has no attribute 'validate_custom_config'. Did you mean: 'cache_custom_config'?
FAILED backend/tests/unit/infrastructure/resilience/test_validation_schemas.py::TestConfigValidatorIntegration::test_settings_validate_external_json - AttributeError: 'Settings' object has no attribute 'validate_custom_config'. Did you mean: 'cache_custom_config'?
FAILED backend/tests/unit/infrastructure/resilience/test_validation_schemas.py::TestConfigValidatorIntegration::test_settings_validate_invalid_custom_config - AttributeError: 'Settings' object has no attribute 'validate_custom_config'. Did you mean: 'cache_custom_config'?
FAILED backend/tests/unit/infrastructure/security/test_auth_dependencies.py::TestAuthenticationDependencyEdgeCases::test_dependencies_handle_concurrent_access_safely - AssertionError: assert 'development' == 'test-primary-key-123'
FAILED backend/tests/unit/infrastructure/security/test_auth_dependencies.py::TestVerifyApiKeyDependency::test_verify_api_key_handles_environment_detection_failure - AssertionError: assert 'development' == 'test-primary-key-123'
FAILED backend/tests/unit/infrastructure/security/test_auth_dependencies.py::TestVerifyApiKeyDependency::test_verify_api_key_succeeds_with_valid_credentials - AssertionError: assert 'development' == 'test-primary-key-123'
FAILED backend/tests/unit/infrastructure/security/test_auth_utilities.py::TestSupportsFeatureUtility::test_supports_feature_rate_limiting_capability - assert False is True
FAILED backend/tests/unit/infrastructure/security/test_auth_utilities.py::TestSupportsFeatureUtility::test_supports_feature_request_logging_flag - assert False is True
FAILED backend/tests/unit/infrastructure/security/test_auth_utilities.py::TestVerifyApiKeyStringUtility::test_verify_api_key_string_returns_true_for_valid_key - assert False is True
SKIPPED [1] backend/tests/e2e/cache/test_cache_invalidation_workflow.py:337: Unable to populate sufficient cache entries for behavioral test - may need AI API key
SKIPPED [1] backend/tests/e2e/cache/test_cache_monitoring_workflow.py:329: Metrics endpoint unavailable - skipping precise metrics test
SKIPPED [1] backend/tests/integration/api/internal/test_resilience_performance_endpoints.py:195: need --run-slow option to run
SKIPPED [1] backend/tests/integration/environment/test_end_to_end_validation.py:311: Resilience preset system not available
SKIPPED [1] backend/tests/integration/environment/test_resilience_preset_integration.py:120: Resilience preset system not available
SKIPPED [1] backend/tests/integration/environment/test_resilience_preset_integration.py:161: Resilience preset system not available
SKIPPED [1] backend/tests/integration/environment/test_resilience_preset_integration.py:199: Resilience preset system not available
SKIPPED [1] backend/tests/integration/environment/test_resilience_preset_integration.py:327: Resilience preset system not available
SKIPPED [1] backend/tests/integration/environment/test_resilience_preset_integration.py:368: Resilience preset system not available
SKIPPED [1] backend/tests/integration/environment/test_resilience_preset_integration.py:409: Resilience preset system not available
SKIPPED [1] backend/tests/integration/environment/test_resilience_preset_integration.py:79: Resilience preset system not available
SKIPPED [1] backend/tests/integration/middleware/test_enhanced_middleware_integration.py:516: need --run-slow option to run
SKIPPED [1] backend/tests/integration/middleware/test_enhanced_middleware_integration.py:544: need --run-slow option to run
SKIPPED [1] backend/tests/manual/test_manual_api.py:109: need --run-manual option to run
SKIPPED [1] backend/tests/manual/test_manual_api.py:173: GEMINI_API_KEY not set
SKIPPED [1] backend/tests/manual/test_manual_api.py:208: need --run-manual option to run
SKIPPED [1] backend/tests/manual/test_manual_api.py:74: need --run-manual option to run
SKIPPED [1] backend/tests/performance/test_health_check_performance.py:149: need --run-slow option to run
SKIPPED [1] backend/tests/performance/test_performance_benchmarks.py:185: need --run-slow option to run
SKIPPED [1] backend/tests/performance/test_performance_benchmarks.py:468: need --run-slow option to run
SKIPPED [1] backend/tests/unit/core/middleware/test_rate_limiting_middleware.py: need --run-slow option to run
SKIPPED [1] backend/tests/unit/core/middleware/test_rate_limiting_middleware.py:262: need --run-slow option to run
SKIPPED [1] backend/tests/unit/core/middleware/test_rate_limiting_middleware.py:527: need --run-slow option to run
SKIPPED [1] backend/tests/unit/core/middleware/test_request_size_middleware.py:572: need --run-slow option to run
SKIPPED [1] backend/tests/unit/core/test_config_monitoring.py:420: need --run-slow option to run
SKIPPED [1] backend/tests/unit/infrastructure/resilience/test_presets.py:309: Legacy resilience configuration will be removed soon
SKIPPED [1] backend/tests/unit/infrastructure/resilience/test_resilience.py:1173: need --run-slow option to run
SKIPPED [1] backend/tests/unit/infrastructure/resilience/test_resilience.py:1215: need --run-slow option to run
SKIPPED [1] backend/tests/unit/infrastructure/resilience/test_resilience.py:1291: need --run-slow option to run
SKIPPED [1] backend/tests/unit/infrastructure/resilience/test_resilience.py:1352: need --run-slow option to run
SKIPPED [1] backend/tests/unit/infrastructure/resilience/test_resilience.py:411: need --run-slow option to run
SKIPPED [1] backend/tests/unit/infrastructure/resilience/test_resilience.py:452: need --run-slow option to run
SKIPPED [1] backend/tests/unit/infrastructure/resilience/test_resilience.py:506: need --run-slow option to run
SKIPPED [1] backend/tests/unit/infrastructure/resilience/test_resilience.py:636: need --run-slow option to run
SKIPPED [1] backend/tests/unit/infrastructure/resilience/test_resilience.py:661: need --run-slow option to run
SKIPPED [1] backend/tests/unit/infrastructure/resilience/test_resilience.py:699: need --run-slow option to run
SKIPPED [2] backend/tests/unit/core/middleware/test_api_versioning_middleware.py: need --run-slow option to run
SKIPPED [2] backend/tests/unit/core/middleware/test_compression_middleware.py: need --run-slow option to run
SKIPPED [2] backend/tests/unit/core/middleware/test_request_size_middleware.py: need --run-slow option to run
SKIPPED [24] backend/tests/unit/infrastructure/resilience/test_backward_compatibility.py: Legacy resilience configuration will be removed soon
SKIPPED [7] backend/tests/manual/test_manual_api.py: need --run-manual option to run
SKIPPED [8] backend/tests/unit/infrastructure/resilience/test_backward_compatibility.py:26: Legacy resilience configuration will be removed soon